<mujoco model="humanoid_capsule_legs">
  <compiler coordinate="local" angle="radian" balanceinertia="true"/>
  <option timestep="0.001" iterations="100" tolerance="1e-8" integrator="implicitfast"/>
  <default>
    <motor ctrlrange="-1 1" ctrllimited="true"/>
    <joint limited="true" solimplimit="0 .99 .01"/>
    <geom condim="3" friction="1 0.05 0.05" solimp=".9 .99 .01" solref=".02 1" margin="0.004" contype="1" conaffinity="1" rgba="0.8 0.6 .4 1"/>
  </default>
  <asset>
    <texture type="skybox" builtin="gradient" rgb1=".4 .5 .6" rgb2="0 0 0" width="100" height="100"/>
    <texture builtin="flat" height="1278" mark="cross" markrgb="1 1 1" name="texgeom" random="0.01" rgb1="0.8 0.6 0.4" rgb2="0.8 0.6 0.4" type="cube" width="127"/>
    <texture name="texplane" type="2d" builtin="checker" rgb1=".2 .3 .4" rgb2=".1 0.15 0.2" width="100" height="100"/><material name="MatPlane" reflectance="0.5" texture="texplane" texrepeat="1 1" texuniform="true"/><material name="geom" texture="texgeom" texuniform="true"/>
    <mesh file="725669fe-0b05-464b-a3ef-25dd03fd9762/geom/Torso.stl" name="Torso_mesh"/>
    <mesh file="725669fe-0b05-464b-a3ef-25dd03fd9762/geom/Spine.stl" name="Spine_mesh"/>
    <mesh file="725669fe-0b05-464b-a3ef-25dd03fd9762/geom/Chest.stl" name="Chest_mesh"/>
    <mesh file="725669fe-0b05-464b-a3ef-25dd03fd9762/geom/Neck.stl" name="Neck_mesh"/>
    <mesh file="725669fe-0b05-464b-a3ef-25dd03fd9762/geom/L_Thorax.stl" name="L_Thorax_mesh"/>
    <mesh file="725669fe-0b05-464b-a3ef-25dd03fd9762/geom/R_Thorax.stl" name="R_Thorax_mesh"/>
    <mesh file="725669fe-0b05-464b-a3ef-25dd03fd9762/geom/L_Index1.stl" name="L_Index1_mesh"/>
    <mesh file="725669fe-0b05-464b-a3ef-25dd03fd9762/geom/L_Index2.stl" name="L_Index2_mesh"/>
    <mesh file="725669fe-0b05-464b-a3ef-25dd03fd9762/geom/L_Index3.stl" name="L_Index3_mesh"/>
    <mesh file="725669fe-0b05-464b-a3ef-25dd03fd9762/geom/L_Middle1.stl" name="L_Middle1_mesh"/>
    <mesh file="725669fe-0b05-464b-a3ef-25dd03fd9762/geom/L_Middle2.stl" name="L_Middle2_mesh"/>
    <mesh file="725669fe-0b05-464b-a3ef-25dd03fd9762/geom/L_Middle3.stl" name="L_Middle3_mesh"/>
    <mesh file="725669fe-0b05-464b-a3ef-25dd03fd9762/geom/L_Pinky1.stl" name="L_Pinky1_mesh"/>
    <mesh file="725669fe-0b05-464b-a3ef-25dd03fd9762/geom/L_Pinky2.stl" name="L_Pinky2_mesh"/>
    <mesh file="725669fe-0b05-464b-a3ef-25dd03fd9762/geom/L_Pinky3.stl" name="L_Pinky3_mesh"/>
    <mesh file="725669fe-0b05-464b-a3ef-25dd03fd9762/geom/L_Ring1.stl" name="L_Ring1_mesh"/>
    <mesh file="725669fe-0b05-464b-a3ef-25dd03fd9762/geom/L_Ring2.stl" name="L_Ring2_mesh"/>
    <mesh file="725669fe-0b05-464b-a3ef-25dd03fd9762/geom/L_Ring3.stl" name="L_Ring3_mesh"/>
    <mesh file="725669fe-0b05-464b-a3ef-25dd03fd9762/geom/L_Thumb1.stl" name="L_Thumb1_mesh"/>
    <mesh file="725669fe-0b05-464b-a3ef-25dd03fd9762/geom/L_Thumb2.stl" name="L_Thumb2_mesh"/>
    <mesh file="725669fe-0b05-464b-a3ef-25dd03fd9762/geom/L_Thumb3.stl" name="L_Thumb3_mesh"/>
    <mesh file="725669fe-0b05-464b-a3ef-25dd03fd9762/geom/R_Index1.stl" name="R_Index1_mesh"/>
    <mesh file="725669fe-0b05-464b-a3ef-25dd03fd9762/geom/R_Index2.stl" name="R_Index2_mesh"/>
    <mesh file="725669fe-0b05-464b-a3ef-25dd03fd9762/geom/R_Index3.stl" name="R_Index3_mesh"/>
    <mesh file="725669fe-0b05-464b-a3ef-25dd03fd9762/geom/R_Middle1.stl" name="R_Middle1_mesh"/>
    <mesh file="725669fe-0b05-464b-a3ef-25dd03fd9762/geom/R_Middle2.stl" name="R_Middle2_mesh"/>
    <mesh file="725669fe-0b05-464b-a3ef-25dd03fd9762/geom/R_Middle3.stl" name="R_Middle3_mesh"/>
    <mesh file="725669fe-0b05-464b-a3ef-25dd03fd9762/geom/R_Pinky1.stl" name="R_Pinky1_mesh"/>
    <mesh file="725669fe-0b05-464b-a3ef-25dd03fd9762/geom/R_Pinky2.stl" name="R_Pinky2_mesh"/>
    <mesh file="725669fe-0b05-464b-a3ef-25dd03fd9762/geom/R_Pinky3.stl" name="R_Pinky3_mesh"/>
    <mesh file="725669fe-0b05-464b-a3ef-25dd03fd9762/geom/R_Ring1.stl" name="R_Ring1_mesh"/>
    <mesh file="725669fe-0b05-464b-a3ef-25dd03fd9762/geom/R_Ring2.stl" name="R_Ring2_mesh"/>
    <mesh file="725669fe-0b05-464b-a3ef-25dd03fd9762/geom/R_Ring3.stl" name="R_Ring3_mesh"/>
    <mesh file="725669fe-0b05-464b-a3ef-25dd03fd9762/geom/R_Thumb1.stl" name="R_Thumb1_mesh"/>
    <mesh file="725669fe-0b05-464b-a3ef-25dd03fd9762/geom/R_Thumb2.stl" name="R_Thumb2_mesh"/>
    <mesh file="725669fe-0b05-464b-a3ef-25dd03fd9762/geom/R_Thumb3.stl" name="R_Thumb3_mesh"/>
  </asset>
  <worldbody>
    <light name="tracking_light" pos="0 0 7" dir="0 0 -1" directional="true" cutoff="100" exponent="1" diffuse="1 1 1" specular="0.1 0.1 0.1" mode="trackcom"/><camera name="back" pos="0 3 2.4" xyaxes="-1 0 0 0 -1 2" mode="trackcom"/><camera name="side" pos="-3 0 2.4" xyaxes="0 -1 0 1 0 2" mode="trackcom"/><camera name="front_side" pos="-2 -2 .8" xyaxes="0.5 -0.5 0 0.1 0.1 1" mode="trackcom"/><geom conaffinity="1" condim="3" name="floor" pos="0 0 0" friction="1 0.05 0.05" solimp=".9 .99 .01" solref=".02 1" rgba="0.8 0.9 0.8 1" size="100 100 .2" type="plane" material="MatPlane"/>
    <body name="Pelvis" pos="0.0031 -0.3514 0.947">
      <freejoint name="Pelvis"/>
      <geom type="capsule" density="2000" fromto="0 0 -0.06 0 0 0.06" size="0.09" contype="1" conaffinity="1"/>
      <body name="L_Hip" pos="-0.026 0.0582 -0.0928">
        <joint name="L_Hip_x" type="hinge" pos="0 0 0" axis="1 0 0" actuatorfrcrange="-300 300" stiffness="0" damping="0" armature="0.02" range="-0.5236 1.5708"/>
        <joint name="L_Hip_y" type="hinge" pos="0 0 0" axis="0 1 0" actuatorfrcrange="-300 300" stiffness="0" damping="0" armature="0.02" range="-2.4435 1.0472"/>
        <joint name="L_Hip_z" type="hinge" pos="0 0 0" axis="0 0 1" actuatorfrcrange="-300 300" stiffness="0" damping="0" armature="0.02" range="-0.6109 1.0472"/>
        <geom type="capsule" density="1500" fromto="0 0 0 -0.0094 0.0547 -0.3788" size="0.055" contype="1" conaffinity="1"/>
        <body name="L_Knee" pos="-0.0094 0.0547 -0.3788">
          <joint name="L_Knee_x" type="hinge" pos="0 0 0" axis="1 0 0" actuatorfrcrange="-200 200" stiffness="0" damping="0" armature="0.02" range="-0.5236 0.5236"/>
          <joint name="L_Knee_y" type="hinge" pos="0 0 0" axis="0 1 0" actuatorfrcrange="-200 200" stiffness="0" damping="0" armature="0.02" range="0 2.7925"/>
          <joint name="L_Knee_z" type="hinge" pos="0 0 0" axis="0 0 1" actuatorfrcrange="-200 200" stiffness="0" damping="0" armature="0.02" range="-0.5236 0.5236"/>
          <geom type="capsule" density="1250" fromto="0 0 0 -0.0319 -0.0435 -0.4031" size="0.05" contype="1" conaffinity="1"/>
          <body name="L_Ankle" pos="-0.0319 -0.0435 -0.4031">
            <joint name="L_Ankle_x" type="hinge" pos="0 0 0" axis="1 0 0" actuatorfrcrange="-100 100" stiffness="0" damping="0" armature="0.02" range="-0.5236 0.5236"/>
            <joint name="L_Ankle_y" type="hinge" pos="0 0 0" axis="0 1 0" actuatorfrcrange="-100 100" stiffness="0" damping="0" armature="0.02" range="-0.9599 0.9599"/>
            <joint name="L_Ankle_z" type="hinge" pos="0 0 0" axis="0 0 1" actuatorfrcrange="-100 100" stiffness="0" damping="0" armature="0.02" range="-0.6981 0.6981"/>
            <geom density="445.8198" type="box" pos="0.0232 0.0407 -0.0287" size="0.0857 0.0498 0.0463" quat="1.0000 0.0000 0.0000 0.0000"/>
            <body name="L_Toe" pos="0.1182 0.0473 -0.058">
              <joint name="L_Toe_x" type="hinge" pos="0 0 0" axis="1 0 0" actuatorfrcrange="-75 75" stiffness="0" damping="0" armature="0.02" range="-0.5236 0.5236"/>
              <joint name="L_Toe_y" type="hinge" pos="0 0 0" axis="0 1 0" actuatorfrcrange="-75 75" stiffness="0" damping="0" armature="0.02" range="-1.0472 1.0472"/>
              <joint name="L_Toe_z" type="hinge" pos="0 0 0" axis="0 0 1" actuatorfrcrange="-75 75" stiffness="0" damping="0" armature="0.02" range="-0.5236 0.5236"/>
              <geom density="421.76654" type="box" pos="0.0256 -0.0065 0.0034" size="0.0495 0.0478 0.0205" quat="1.0000 0.0000 0.0000 0.0000"/>
            </body>
          </body>
        </body>
      </body>
      <body name="R_Hip" pos="-0.0213 -0.0633 -0.1039">
        <joint name="R_Hip_x" type="hinge" pos="0 0 0" axis="1 0 0" actuatorfrcrange="-300 300" stiffness="0" damping="0" armature="0.02" range="-1.5708 0.5236"/>
        <joint name="R_Hip_y" type="hinge" pos="0 0 0" axis="0 1 0" actuatorfrcrange="-300 300" stiffness="0" damping="0" armature="0.02" range="-2.4435 1.0472"/>
        <joint name="R_Hip_z" type="hinge" pos="0 0 0" axis="0 0 1" actuatorfrcrange="-300 300" stiffness="0" damping="0" armature="0.02" range="-1.0472 0.6109"/>
        <geom type="capsule" density="1500" fromto="0 0 0 -0.0168 -0.0442 -0.3624" size="0.055" contype="1" conaffinity="1"/>
        <body name="R_Knee" pos="-0.0168 -0.0442 -0.3624">
          <joint name="R_Knee_x" type="hinge" pos="0 0 0" axis="1 0 0" actuatorfrcrange="-200 200" stiffness="0" damping="0" armature="0.02" range="-0.5236 0.5236"/>
          <joint name="R_Knee_y" type="hinge" pos="0 0 0" axis="0 1 0" actuatorfrcrange="-200 200" stiffness="0" damping="0" armature="0.02" range="0 2.7925"/>
          <joint name="R_Knee_z" type="hinge" pos="0 0 0" axis="0 0 1" actuatorfrcrange="-200 200" stiffness="0" damping="0" armature="0.02" range="-0.5236 0.5236"/>
          <geom type="capsule" density="1250" fromto="0 0 0 -0.0202 0.0154 -0.4107" size="0.05" contype="1" conaffinity="1"/>
          <body name="R_Ankle" pos="-0.0202 0.0154 -0.4107">
            <joint name="R_Ankle_x" type="hinge" pos="0 0 0" axis="1 0 0" actuatorfrcrange="-100 100" stiffness="0" damping="0" armature="0.02" range="-0.5236 0.5236"/>
            <joint name="R_Ankle_y" type="hinge" pos="0 0 0" axis="0 1 0" actuatorfrcrange="-100 100" stiffness="0" damping="0" armature="0.02" range="-0.9599 0.9599"/>
            <joint name="R_Ankle_z" type="hinge" pos="0 0 0" axis="0 0 1" actuatorfrcrange="-100 100" stiffness="0" damping="0" armature="0.02" range="-0.6981 0.6981"/>
            <geom density="445.80768" type="box" pos="0.0142 -0.0243 -0.0263" size="0.0857 0.0498 0.0464" quat="1.0000 0.0000 0.0000 0.0000"/>
            <body name="R_Toe" pos="0.119 -0.0388 -0.0583">
              <joint name="R_Toe_x" type="hinge" pos="0 0 0" axis="1 0 0" actuatorfrcrange="-75 75" stiffness="0" damping="0" armature="0.02" range="-0.5236 0.5236"/>
              <joint name="R_Toe_y" type="hinge" pos="0 0 0" axis="0 1 0" actuatorfrcrange="-75 75" stiffness="0" damping="0" armature="0.02" range="-1.0472 1.0472"/>
              <joint name="R_Toe_z" type="hinge" pos="0 0 0" axis="0 0 1" actuatorfrcrange="-75 75" stiffness="0" damping="0" armature="0.02" range="-0.5236 0.5236"/>
              <geom density="421.76465" type="box" pos="0.0158 0.0145 0.0062" size="0.0495 0.0478 0.0205" quat="1.0000 0.0000 0.0000 0.0000"/>
            </body>
          </body>
        </body>
      </body>
      <body name="Torso" pos="-0.0276 -0.0028 0.1099">
        <joint name="Torso_x" type="hinge" pos="0 0 0" axis="1 0 0" actuatorfrcrange="-300 300" stiffness="0" damping="0" armature="0.02" range="-1.0472 1.0472"/>
        <joint name="Torso_y" type="hinge" pos="0 0 0" axis="0 1 0" actuatorfrcrange="-300 300" stiffness="0" damping="0" armature="0.02" range="-1.0472 1.5708"/>
        <joint name="Torso_z" type="hinge" pos="0 0 0" axis="0 0 1" actuatorfrcrange="-300 300" stiffness="0" damping="0" armature="0.02" range="-0.8727 0.8727"/>
        <geom type="mesh" mesh="Torso_mesh" density="1000" contype="1" conaffinity="1"/>
        <body name="Spine" pos="-0.0059 0.0094 0.1319">
          <joint name="Spine_x" type="hinge" pos="0 0 0" axis="1 0 0" actuatorfrcrange="-200 200" stiffness="0" damping="0" armature="0.02" range="-1.0472 1.0472"/>
          <joint name="Spine_y" type="hinge" pos="0 0 0" axis="0 1 0" actuatorfrcrange="-200 200" stiffness="0" damping="0" armature="0.02" range="-1.0472 1.5708"/>
          <joint name="Spine_z" type="hinge" pos="0 0 0" axis="0 0 1" actuatorfrcrange="-200 200" stiffness="0" damping="0" armature="0.02" range="-0.8727 0.8727"/>
          <geom type="mesh" mesh="Spine_mesh" density="1000" contype="1" conaffinity="1"/>
          <body name="Chest" pos="0.0284 -0.0113 0.0522">
            <joint name="Chest_x" type="hinge" pos="0 0 0" axis="1 0 0" actuatorfrcrange="-150 150" stiffness="0" damping="0" armature="0.02" range="-1.0472 1.0472"/>
            <joint name="Chest_y" type="hinge" pos="0 0 0" axis="0 1 0" actuatorfrcrange="-150 150" stiffness="0" damping="0" armature="0.02" range="-1.0472 1.5708"/>
            <joint name="Chest_z" type="hinge" pos="0 0 0" axis="0 0 1" actuatorfrcrange="-150 150" stiffness="0" damping="0" armature="0.02" range="-0.8727 0.8727"/>
            <geom type="mesh" mesh="Chest_mesh" density="1000" contype="1" conaffinity="1"/>
            <body name="Neck" pos="-0.0316 -0.0122 0.1652">
              <joint name="Neck_x" type="hinge" pos="0 0 0" axis="1 0 0" actuatorfrcrange="-75 75" stiffness="0" damping="0" armature="0.02" range="-0.8727 0.8727"/>
              <joint name="Neck_y" type="hinge" pos="0 0 0" axis="0 1 0" actuatorfrcrange="-75 75" stiffness="0" damping="0" armature="0.02" range="-0.6981 1.0472"/>
              <joint name="Neck_z" type="hinge" pos="0 0 0" axis="0 0 1" actuatorfrcrange="-75 75" stiffness="0" damping="0" armature="0.02" range="-0.7854 0.7854"/>
              <geom type="mesh" mesh="Neck_mesh" density="1000" contype="1" conaffinity="1"/>
              <body name="Head" pos="0.0207 0.0248 0.1605">
                <joint name="Head_x" type="hinge" pos="0 0 0" axis="1 0 0" actuatorfrcrange="-25 25" stiffness="0" damping="0" armature="0.02" range="-0.8727 0.8727"/>
                <joint name="Head_y" type="hinge" pos="0 0 0" axis="0 1 0" actuatorfrcrange="-25 25" stiffness="0" damping="0" armature="0.02" range="-0.6981 1.0472"/>
                <joint name="Head_z" type="hinge" pos="0 0 0" axis="0 0 1" actuatorfrcrange="-25 25" stiffness="0" damping="0" armature="0.02" range="-0.7854 0.7854"/>
                <geom type="sphere" density="1000" size="0.155" pos="-0.0056 -0.0202 0.0471" contype="1" conaffinity="1"/>
              </body>
            </body>
            <body name="L_Thorax" pos="-0.0072 0.0464 0.0849">
              <joint name="L_Thorax_x" type="hinge" pos="0 0 0" axis="1 0 0" actuatorfrcrange="-200 200" stiffness="0" damping="0" armature="0.02" range="-0.6981 0.5236"/>
              <joint name="L_Thorax_y" type="hinge" pos="0 0 0" axis="0 1 0" actuatorfrcrange="-200 200" stiffness="0" damping="0" armature="0.02" range="-0.5236 0.5236"/>
              <joint name="L_Thorax_z" type="hinge" pos="0 0 0" axis="0 0 1" actuatorfrcrange="-200 200" stiffness="0" damping="0" armature="0.02" range="-0.5236 0.5236"/>
              <geom type="mesh" mesh="L_Thorax_mesh" density="1000" contype="1" conaffinity="1"/>
              <body name="L_Shoulder" pos="-0.0155 0.1192 0.0577">
                <joint name="L_Shoulder_x" type="hinge" pos="0 0 0" axis="1 0 0" actuatorfrcrange="-150 150" stiffness="0" damping="0" armature="0.02" range="-2.3562 1.5708"/>
                <joint name="L_Shoulder_y" type="hinge" pos="0 0 0" axis="0 1 0" actuatorfrcrange="-150 150" stiffness="0" damping="0" armature="0.02" range="-1.5708 1.5708"/>
                <joint name="L_Shoulder_z" type="hinge" pos="0 0 0" axis="0 0 1" actuatorfrcrange="-150 150" stiffness="0" damping="0" armature="0.02" range="-2.7925 1.0472"/>
                <geom type="capsule" density="1000" fromto="0 0 0 -0.0425 0.2541 -0.0722" size="0.092" contype="1" conaffinity="1"/>
                <body name="L_Elbow" pos="-0.0425 0.2541 -0.0722">
                  <joint name="L_Elbow_x" type="hinge" pos="0 0 0" axis="1 0 0" actuatorfrcrange="-100 100" stiffness="0" damping="0" armature="0.02" range="-0.5236 0.5236"/>
                  <joint name="L_Elbow_y" type="hinge" pos="0 0 0" axis="0 1 0" actuatorfrcrange="-100 100" stiffness="0" damping="0" armature="0.02" range="-0.5236 0.5236"/>
                  <joint name="L_Elbow_z" type="hinge" pos="0 0 0" axis="0 0 1" actuatorfrcrange="-100 100" stiffness="0" damping="0" armature="0.02" range="-2.7925 0"/>
                  <geom type="capsule" density="1000" fromto="0 0 0 -0.0025 0.252 0.0232" size="0.075" contype="1" conaffinity="1"/>
                  <body name="L_Wrist" pos="-0.0025 0.252 0.0232">
                    <joint name="L_Wrist_x" type="hinge" pos="0 0 0" axis="1 0 0" actuatorfrcrange="-75 75" stiffness="0" damping="0" armature="0.02" range="-1.5708 1.5708"/>
                    <joint name="L_Wrist_y" type="hinge" pos="0 0 0" axis="0 1 0" actuatorfrcrange="-75 75" stiffness="0" damping="0" armature="0.02" range="-1.5708 1.5708"/>
                    <joint name="L_Wrist_z" type="hinge" pos="0 0 0" axis="0 0 1" actuatorfrcrange="-75 75" stiffness="0" damping="0" armature="0.02" range="-1.0472 1.0472"/>
                    <geom type="capsule" density="1000" fromto="0 0 0 -0.004 0.1094 -0.0063" size="0.048" contype="1" conaffinity="1"/>
                    <body name="L_Index1" pos="0.0194 0.1019 -0.0087">
                      <joint name="L_Index1_x" type="hinge" pos="0 0 0" axis="1 0 0" actuatorfrcrange="0 0" stiffness="0" damping="40" armature="1" range="-1e-6 1e-6"/>
                      <joint name="L_Index1_y" type="hinge" pos="0 0 0" axis="0 1 0" actuatorfrcrange="0 0" stiffness="0" damping="40" armature="1" range="-1e-6 1e-6"/>
                      <joint name="L_Index1_z" type="hinge" pos="0 0 0" axis="0 0 1" actuatorfrcrange="0 0" stiffness="0" damping="40" armature="1" range="-1e-6 1e-6"/>
                      <geom type="mesh" mesh="L_Index1_mesh" density="1000" contype="1" conaffinity="1"/>
                      <body name="L_Index2" pos="0.003 0.0319 0.0022">
                        <joint name="L_Index2_x" type="hinge" pos="0 0 0" axis="1 0 0" actuatorfrcrange="0 0" stiffness="0" damping="40" armature="1" range="-1e-6 1e-6"/>
                        <joint name="L_Index2_y" type="hinge" pos="0 0 0" axis="0 1 0" actuatorfrcrange="0 0" stiffness="0" damping="40" armature="1" range="-1e-6 1e-6"/>
                        <joint name="L_Index2_z" type="hinge" pos="0 0 0" axis="0 0 1" actuatorfrcrange="0 0" stiffness="0" damping="40" armature="1" range="-1e-6 1e-6"/>
                        <geom type="mesh" mesh="L_Index2_mesh" density="1000" contype="1" conaffinity="1"/>
                        <body name="L_Index3" pos="0.0001 0.0225 -0.0024">
                          <joint name="L_Index3_x" type="hinge" pos="0 0 0" axis="1 0 0" actuatorfrcrange="0 0" stiffness="0" damping="40" armature="1" range="-1e-6 1e-6"/>
                          <joint name="L_Index3_y" type="hinge" pos="0 0 0" axis="0 1 0" actuatorfrcrange="0 0" stiffness="0" damping="40" armature="1" range="-1e-6 1e-6"/>
                          <joint name="L_Index3_z" type="hinge" pos="0 0 0" axis="0 0 1" actuatorfrcrange="0 0" stiffness="0" damping="40" armature="1" range="-1e-6 1e-6"/>
                          <geom type="mesh" mesh="L_Index3_mesh" density="1000" contype="1" conaffinity="1"/>
                        </body>
                      </body>
                    </body>
                    <body name="L_Middle1" pos="-0.004 0.1094 -0.0063">
                      <joint name="L_Middle1_x" type="hinge" pos="0 0 0" axis="1 0 0" actuatorfrcrange="0 0" stiffness="0" damping="40" armature="1" range="-1e-6 1e-6"/>
                      <joint name="L_Middle1_y" type="hinge" pos="0 0 0" axis="0 1 0" actuatorfrcrange="0 0" stiffness="0" damping="40" armature="1" range="-1e-6 1e-6"/>
                      <joint name="L_Middle1_z" type="hinge" pos="0 0 0" axis="0 0 1" actuatorfrcrange="0 0" stiffness="0" damping="40" armature="1" range="-1e-6 1e-6"/>
                      <geom type="mesh" mesh="L_Middle1_mesh" density="1000" contype="1" conaffinity="1"/>
                      <body name="L_Middle2" pos="-0.004 0.0306 0.0008">
                        <joint name="L_Middle2_x" type="hinge" pos="0 0 0" axis="1 0 0" actuatorfrcrange="0 0" stiffness="0" damping="40" armature="1" range="-1e-6 1e-6"/>
                        <joint name="L_Middle2_y" type="hinge" pos="0 0 0" axis="0 1 0" actuatorfrcrange="0 0" stiffness="0" damping="40" armature="1" range="-1e-6 1e-6"/>
                        <joint name="L_Middle2_z" type="hinge" pos="0 0 0" axis="0 0 1" actuatorfrcrange="0 0" stiffness="0" damping="40" armature="1" range="-1e-6 1e-6"/>
                        <geom type="mesh" mesh="L_Middle2_mesh" density="1000" contype="1" conaffinity="1"/>
                        <body name="L_Middle3" pos="-0.0041 0.0235 -0.002">
                          <joint name="L_Middle3_x" type="hinge" pos="0 0 0" axis="1 0 0" actuatorfrcrange="0 0" stiffness="0" damping="40" armature="1" range="-1e-6 1e-6"/>
                          <joint name="L_Middle3_y" type="hinge" pos="0 0 0" axis="0 1 0" actuatorfrcrange="0 0" stiffness="0" damping="40" armature="1" range="-1e-6 1e-6"/>
                          <joint name="L_Middle3_z" type="hinge" pos="0 0 0" axis="0 0 1" actuatorfrcrange="0 0" stiffness="0" damping="40" armature="1" range="-1e-6 1e-6"/>
                          <geom type="mesh" mesh="L_Middle3_mesh" density="1000" contype="1" conaffinity="1"/>
                        </body>
                      </body>
                    </body>
                    <body name="L_Pinky1" pos="-0.0437 0.084 -0.0145">
                      <joint name="L_Pinky1_x" type="hinge" pos="0 0 0" axis="1 0 0" actuatorfrcrange="0 0" stiffness="0" damping="40" armature="1" range="-1e-6 1e-6"/>
                      <joint name="L_Pinky1_y" type="hinge" pos="0 0 0" axis="0 1 0" actuatorfrcrange="0 0" stiffness="0" damping="40" armature="1" range="-1e-6 1e-6"/>
                      <joint name="L_Pinky1_z" type="hinge" pos="0 0 0" axis="0 0 1" actuatorfrcrange="0 0" stiffness="0" damping="40" armature="1" range="-1e-6 1e-6"/>
                      <geom type="mesh" mesh="L_Pinky1_mesh" density="1000" contype="1" conaffinity="1"/>
                      <body name="L_Pinky2" pos="-0.012 0.0155 -0.0011">
                        <joint name="L_Pinky2_x" type="hinge" pos="0 0 0" axis="1 0 0" actuatorfrcrange="0 0" stiffness="0" damping="40" armature="1" range="-1e-6 1e-6"/>
                        <joint name="L_Pinky2_y" type="hinge" pos="0 0 0" axis="0 1 0" actuatorfrcrange="0 0" stiffness="0" damping="40" armature="1" range="-1e-6 1e-6"/>
                        <joint name="L_Pinky2_z" type="hinge" pos="0 0 0" axis="0 0 1" actuatorfrcrange="0 0" stiffness="0" damping="40" armature="1" range="-1e-6 1e-6"/>
                        <geom type="mesh" mesh="L_Pinky2_mesh" density="1000" contype="1" conaffinity="1"/>
                        <body name="L_Pinky3" pos="-0.0112 0.0155 -0.0017">
                          <joint name="L_Pinky3_x" type="hinge" pos="0 0 0" axis="1 0 0" actuatorfrcrange="0 0" stiffness="0" damping="40" armature="1" range="-1e-6 1e-6"/>
                          <joint name="L_Pinky3_y" type="hinge" pos="0 0 0" axis="0 1 0" actuatorfrcrange="0 0" stiffness="0" damping="40" armature="1" range="-1e-6 1e-6"/>
                          <joint name="L_Pinky3_z" type="hinge" pos="0 0 0" axis="0 0 1" actuatorfrcrange="0 0" stiffness="0" damping="40" armature="1" range="-1e-6 1e-6"/>
                          <geom type="mesh" mesh="L_Pinky3_mesh" density="1000" contype="1" conaffinity="1"/>
                        </body>
                      </body>
                    </body>
                    <body name="L_Ring1" pos="-0.0273 0.0974 -0.0093">
                      <joint name="L_Ring1_x" type="hinge" pos="0 0 0" axis="1 0 0" actuatorfrcrange="0 0" stiffness="0" damping="40" armature="1" range="-1e-6 1e-6"/>
                      <joint name="L_Ring1_y" type="hinge" pos="0 0 0" axis="0 1 0" actuatorfrcrange="0 0" stiffness="0" damping="40" armature="1" range="-1e-6 1e-6"/>
                      <joint name="L_Ring1_z" type="hinge" pos="0 0 0" axis="0 0 1" actuatorfrcrange="0 0" stiffness="0" damping="40" armature="1" range="-1e-6 1e-6"/>
                      <geom type="mesh" mesh="L_Ring1_mesh" density="1000" contype="1" conaffinity="1"/>
                      <body name="L_Ring2" pos="-0.0053 0.028 0.0015">
                        <joint name="L_Ring2_x" type="hinge" pos="0 0 0" axis="1 0 0" actuatorfrcrange="0 0" stiffness="0" damping="40" armature="1" range="-1e-6 1e-6"/>
                        <joint name="L_Ring2_y" type="hinge" pos="0 0 0" axis="0 1 0" actuatorfrcrange="0 0" stiffness="0" damping="40" armature="1" range="-1e-6 1e-6"/>
                        <joint name="L_Ring2_z" type="hinge" pos="0 0 0" axis="0 0 1" actuatorfrcrange="0 0" stiffness="0" damping="40" armature="1" range="-1e-6 1e-6"/>
                        <geom type="mesh" mesh="L_Ring2_mesh" density="1000" contype="1" conaffinity="1"/>
                        <body name="L_Ring3" pos="-0.0071 0.0228 -0.0015">
                          <joint name="L_Ring3_x" type="hinge" pos="0 0 0" axis="1 0 0" actuatorfrcrange="0 0" stiffness="0" damping="40" armature="1" range="-1e-6 1e-6"/>
                          <joint name="L_Ring3_y" type="hinge" pos="0 0 0" axis="0 1 0" actuatorfrcrange="0 0" stiffness="0" damping="40" armature="1" range="-1e-6 1e-6"/>
                          <joint name="L_Ring3_z" type="hinge" pos="0 0 0" axis="0 0 1" actuatorfrcrange="0 0" stiffness="0" damping="40" armature="1" range="-1e-6 1e-6"/>
                          <geom type="mesh" mesh="L_Ring3_mesh" density="1000" contype="1" conaffinity="1"/>
                        </body>
                      </body>
                    </body>
                    <body name="L_Thumb1" pos="0.0256 0.0406 -0.018">
                      <joint name="L_Thumb1_x" type="hinge" pos="0 0 0" axis="1 0 0" actuatorfrcrange="0 0" stiffness="0" damping="40" armature="1" range="-1e-6 1e-6"/>
                      <joint name="L_Thumb1_y" type="hinge" pos="0 0 0" axis="0 1 0" actuatorfrcrange="0 0" stiffness="0" damping="40" armature="1" range="-1e-6 1e-6"/>
                      <joint name="L_Thumb1_z" type="hinge" pos="0 0 0" axis="0 0 1" actuatorfrcrange="0 0" stiffness="0" damping="40" armature="1" range="-1e-6 1e-6"/>
                      <geom type="mesh" mesh="L_Thumb1_mesh" density="1000" contype="1" conaffinity="1"/>
                      <body name="L_Thumb2" pos="0.025 0.017 0.001">
                        <joint name="L_Thumb2_x" type="hinge" pos="0 0 0" axis="1 0 0" actuatorfrcrange="0 0" stiffness="0" damping="40" armature="1" range="-1e-6 1e-6"/>
                        <joint name="L_Thumb2_y" type="hinge" pos="0 0 0" axis="0 1 0" actuatorfrcrange="0 0" stiffness="0" damping="40" armature="1" range="-1e-6 1e-6"/>
                        <joint name="L_Thumb2_z" type="hinge" pos="0 0 0" axis="0 0 1" actuatorfrcrange="0 0" stiffness="0" damping="40" armature="1" range="-1e-6 1e-6"/>
                        <geom type="mesh" mesh="L_Thumb2_mesh" density="1000" contype="1" conaffinity="1"/>
                        <body name="L_Thumb3" pos="0.0155 0.0205 -0.0052">
                          <joint name="L_Thumb3_x" type="hinge" pos="0 0 0" axis="1 0 0" actuatorfrcrange="0 0" stiffness="0" damping="40" armature="1" range="-1e-6 1e-6"/>
                          <joint name="L_Thumb3_y" type="hinge" pos="0 0 0" axis="0 1 0" actuatorfrcrange="0 0" stiffness="0" damping="40" armature="1" range="-1e-6 1e-6"/>
                          <joint name="L_Thumb3_z" type="hinge" pos="0 0 0" axis="0 0 1" actuatorfrcrange="0 0" stiffness="0" damping="40" armature="1" range="-1e-6 1e-6"/>
                          <geom type="mesh" mesh="L_Thumb3_mesh" density="1000" contype="1" conaffinity="1"/>
                        </body>
                      </body>
                    </body>
                  </body>
                </body>
              </body>
            </body>
            <body name="R_Thorax" pos="-0.0134 -0.0477 0.0843">
              <joint name="R_Thorax_x" type="hinge" pos="0 0 0" axis="1 0 0" actuatorfrcrange="-200 200" stiffness="0" damping="0" armature="0.02" range="-0.5236 0.6981"/>
              <joint name="R_Thorax_y" type="hinge" pos="0 0 0" axis="0 1 0" actuatorfrcrange="-200 200" stiffness="0" damping="0" armature="0.02" range="-0.5236 0.5236"/>
              <joint name="R_Thorax_z" type="hinge" pos="0 0 0" axis="0 0 1" actuatorfrcrange="-200 200" stiffness="0" damping="0" armature="0.02" range="-0.5236 0.5236"/>
              <geom type="mesh" mesh="R_Thorax_mesh" density="1000" contype="1" conaffinity="1"/>
              <body name="R_Shoulder" pos="-0.0127 -0.1026 0.0535">
                <joint name="R_Shoulder_x" type="hinge" pos="0 0 0" axis="1 0 0" actuatorfrcrange="-150 150" stiffness="0" damping="0" armature="0.02" range="-1.5708 2.3562"/>
                <joint name="R_Shoulder_y" type="hinge" pos="0 0 0" axis="0 1 0" actuatorfrcrange="-150 150" stiffness="0" damping="0" armature="0.02" range="-1.5708 1.5708"/>
                <joint name="R_Shoulder_z" type="hinge" pos="0 0 0" axis="0 0 1" actuatorfrcrange="-150 150" stiffness="0" damping="0" armature="0.02" range="-1.0472 2.7925"/>
                <geom type="capsule" density="1000" fromto="0 0 0 -0.0265 -0.2711 -0.0365" size="0.092" contype="1" conaffinity="1"/>
                <body name="R_Elbow" pos="-0.0265 -0.2711 -0.0365">
                  <joint name="R_Elbow_x" type="hinge" pos="0 0 0" axis="1 0 0" actuatorfrcrange="-100 100" stiffness="0" damping="0" armature="0.02" range="-0.5236 0.5236"/>
                  <joint name="R_Elbow_y" type="hinge" pos="0 0 0" axis="0 1 0" actuatorfrcrange="-100 100" stiffness="0" damping="0" armature="0.02" range="-0.5236 0.5236"/>
                  <joint name="R_Elbow_z" type="hinge" pos="0 0 0" axis="0 0 1" actuatorfrcrange="-100 100" stiffness="0" damping="0" armature="0.02" range="0 2.7925"/>
                  <geom type="capsule" density="1000" fromto="0 0 0 -0.0153 -0.2493 -0.0045" size="0.075" contype="1" conaffinity="1"/>
                  <body name="R_Wrist" pos="-0.0153 -0.2493 -0.0045">
                    <joint name="R_Wrist_x" type="hinge" pos="0 0 0" axis="1 0 0" actuatorfrcrange="-75 75" stiffness="0" damping="0" armature="0.02" range="-1.5708 1.5708"/>
                    <joint name="R_Wrist_y" type="hinge" pos="0 0 0" axis="0 1 0" actuatorfrcrange="-75 75" stiffness="0" damping="0" armature="0.02" range="-1.5708 1.5708"/>
                    <joint name="R_Wrist_z" type="hinge" pos="0 0 0" axis="0 0 1" actuatorfrcrange="-75 75" stiffness="0" damping="0" armature="0.02" range="-1.0472 1.0472"/>
                    <geom type="capsule" density="1000" fromto="0 0 0 -0.0037 -0.1074 -0.0094" size="0.048" contype="1" conaffinity="1"/>
                    <body name="R_Index1" pos="0.0196 -0.0999 -0.0118">
                      <joint name="R_Index1_x" type="hinge" pos="0 0 0" axis="1 0 0" actuatorfrcrange="0 0" stiffness="0" damping="40" armature="1" range="-1e-6 1e-6"/>
                      <joint name="R_Index1_y" type="hinge" pos="0 0 0" axis="0 1 0" actuatorfrcrange="0 0" stiffness="0" damping="40" armature="1" range="-1e-6 1e-6"/>
                      <joint name="R_Index1_z" type="hinge" pos="0 0 0" axis="0 0 1" actuatorfrcrange="0 0" stiffness="0" damping="40" armature="1" range="-1e-6 1e-6"/>
                      <geom type="mesh" mesh="R_Index1_mesh" density="1000" contype="1" conaffinity="1"/>
                      <body name="R_Index2" pos="0.003 -0.0319 0.0022">
                        <joint name="R_Index2_x" type="hinge" pos="0 0 0" axis="1 0 0" actuatorfrcrange="0 0" stiffness="0" damping="40" armature="1" range="-1e-6 1e-6"/>
                        <joint name="R_Index2_y" type="hinge" pos="0 0 0" axis="0 1 0" actuatorfrcrange="0 0" stiffness="0" damping="40" armature="1" range="-1e-6 1e-6"/>
                        <joint name="R_Index2_z" type="hinge" pos="0 0 0" axis="0 0 1" actuatorfrcrange="0 0" stiffness="0" damping="40" armature="1" range="-1e-6 1e-6"/>
                        <geom type="mesh" mesh="R_Index2_mesh" density="1000" contype="1" conaffinity="1"/>
                        <body name="R_Index3" pos="0.0001 -0.0225 -0.0023">
                          <joint name="R_Index3_x" type="hinge" pos="0 0 0" axis="1 0 0" actuatorfrcrange="0 0" stiffness="0" damping="40" armature="1" range="-1e-6 1e-6"/>
                          <joint name="R_Index3_y" type="hinge" pos="0 0 0" axis="0 1 0" actuatorfrcrange="0 0" stiffness="0" damping="40" armature="1" range="-1e-6 1e-6"/>
                          <joint name="R_Index3_z" type="hinge" pos="0 0 0" axis="0 0 1" actuatorfrcrange="0 0" stiffness="0" damping="40" armature="1" range="-1e-6 1e-6"/>
                          <geom type="mesh" mesh="R_Index3_mesh" density="1000" contype="1" conaffinity="1"/>
                        </body>
                      </body>
                    </body>
                    <body name="R_Middle1" pos="-0.0037 -0.1074 -0.0094">
                      <joint name="R_Middle1_x" type="hinge" pos="0 0 0" axis="1 0 0" actuatorfrcrange="0 0" stiffness="0" damping="40" armature="1" range="-1e-6 1e-6"/>
                      <joint name="R_Middle1_y" type="hinge" pos="0 0 0" axis="0 1 0" actuatorfrcrange="0 0" stiffness="0" damping="40" armature="1" range="-1e-6 1e-6"/>
                      <joint name="R_Middle1_z" type="hinge" pos="0 0 0" axis="0 0 1" actuatorfrcrange="0 0" stiffness="0" damping="40" armature="1" range="-1e-6 1e-6"/>
                      <geom type="mesh" mesh="R_Middle1_mesh" density="1000" contype="1" conaffinity="1"/>
                      <body name="R_Middle2" pos="-0.004 -0.0306 0.0008">
                        <joint name="R_Middle2_x" type="hinge" pos="0 0 0" axis="1 0 0" actuatorfrcrange="0 0" stiffness="0" damping="40" armature="1" range="-1e-6 1e-6"/>
                        <joint name="R_Middle2_y" type="hinge" pos="0 0 0" axis="0 1 0" actuatorfrcrange="0 0" stiffness="0" damping="40" armature="1" range="-1e-6 1e-6"/>
                        <joint name="R_Middle2_z" type="hinge" pos="0 0 0" axis="0 0 1" actuatorfrcrange="0 0" stiffness="0" damping="40" armature="1" range="-1e-6 1e-6"/>
                        <geom type="mesh" mesh="R_Middle2_mesh" density="1000" contype="1" conaffinity="1"/>
                        <body name="R_Middle3" pos="-0.0041 -0.0235 -0.002">
                          <joint name="R_Middle3_x" type="hinge" pos="0 0 0" axis="1 0 0" actuatorfrcrange="0 0" stiffness="0" damping="40" armature="1" range="-1e-6 1e-6"/>
                          <joint name="R_Middle3_y" type="hinge" pos="0 0 0" axis="0 1 0" actuatorfrcrange="0 0" stiffness="0" damping="40" armature="1" range="-1e-6 1e-6"/>
                          <joint name="R_Middle3_z" type="hinge" pos="0 0 0" axis="0 0 1" actuatorfrcrange="0 0" stiffness="0" damping="40" armature="1" range="-1e-6 1e-6"/>
                          <geom type="mesh" mesh="R_Middle3_mesh" density="1000" contype="1" conaffinity="1"/>
                        </body>
                      </body>
                    </body>
                    <body name="R_Pinky1" pos="-0.0435 -0.082 -0.0176">
                      <joint name="R_Pinky1_x" type="hinge" pos="0 0 0" axis="1 0 0" actuatorfrcrange="0 0" stiffness="0" damping="40" armature="1" range="-1e-6 1e-6"/>
                      <joint name="R_Pinky1_y" type="hinge" pos="0 0 0" axis="0 1 0" actuatorfrcrange="0 0" stiffness="0" damping="40" armature="1" range="-1e-6 1e-6"/>
                      <joint name="R_Pinky1_z" type="hinge" pos="0 0 0" axis="0 0 1" actuatorfrcrange="0 0" stiffness="0" damping="40" armature="1" range="-1e-6 1e-6"/>
                      <geom type="mesh" mesh="R_Pinky1_mesh" density="1000" contype="1" conaffinity="1"/>
                      <body name="R_Pinky2" pos="-0.012 -0.0155 -0.0011">
                        <joint name="R_Pinky2_x" type="hinge" pos="0 0 0" axis="1 0 0" actuatorfrcrange="0 0" stiffness="0" damping="40" armature="1" range="-1e-6 1e-6"/>
                        <joint name="R_Pinky2_y" type="hinge" pos="0 0 0" axis="0 1 0" actuatorfrcrange="0 0" stiffness="0" damping="40" armature="1" range="-1e-6 1e-6"/>
                        <joint name="R_Pinky2_z" type="hinge" pos="0 0 0" axis="0 0 1" actuatorfrcrange="0 0" stiffness="0" damping="40" armature="1" range="-1e-6 1e-6"/>
                        <geom type="mesh" mesh="R_Pinky2_mesh" density="1000" contype="1" conaffinity="1"/>
                        <body name="R_Pinky3" pos="-0.0112 -0.0155 -0.0017">
                          <joint name="R_Pinky3_x" type="hinge" pos="0 0 0" axis="1 0 0" actuatorfrcrange="0 0" stiffness="0" damping="40" armature="1" range="-1e-6 1e-6"/>
                          <joint name="R_Pinky3_y" type="hinge" pos="0 0 0" axis="0 1 0" actuatorfrcrange="0 0" stiffness="0" damping="40" armature="1" range="-1e-6 1e-6"/>
                          <joint name="R_Pinky3_z" type="hinge" pos="0 0 0" axis="0 0 1" actuatorfrcrange="0 0" stiffness="0" damping="40" armature="1" range="-1e-6 1e-6"/>
                          <geom type="mesh" mesh="R_Pinky3_mesh" density="1000" contype="1" conaffinity="1"/>
                        </body>
                      </body>
                    </body>
                    <body name="R_Ring1" pos="-0.0271 -0.0954 -0.0124">
                      <joint name="R_Ring1_x" type="hinge" pos="0 0 0" axis="1 0 0" actuatorfrcrange="0 0" stiffness="0" damping="40" armature="1" range="-1e-6 1e-6"/>
                      <joint name="R_Ring1_y" type="hinge" pos="0 0 0" axis="0 1 0" actuatorfrcrange="0 0" stiffness="0" damping="40" armature="1" range="-1e-6 1e-6"/>
                      <joint name="R_Ring1_z" type="hinge" pos="0 0 0" axis="0 0 1" actuatorfrcrange="0 0" stiffness="0" damping="40" armature="1" range="-1e-6 1e-6"/>
                      <geom type="mesh" mesh="R_Ring1_mesh" density="1000" contype="1" conaffinity="1"/>
                      <body name="R_Ring2" pos="-0.0053 -0.028 0.0015">
                        <joint name="R_Ring2_x" type="hinge" pos="0 0 0" axis="1 0 0" actuatorfrcrange="0 0" stiffness="0" damping="40" armature="1" range="-1e-6 1e-6"/>
                        <joint name="R_Ring2_y" type="hinge" pos="0 0 0" axis="0 1 0" actuatorfrcrange="0 0" stiffness="0" damping="40" armature="1" range="-1e-6 1e-6"/>
                        <joint name="R_Ring2_z" type="hinge" pos="0 0 0" axis="0 0 1" actuatorfrcrange="0 0" stiffness="0" damping="40" armature="1" range="-1e-6 1e-6"/>
                        <geom type="mesh" mesh="R_Ring2_mesh" density="1000" contype="1" conaffinity="1"/>
                        <body name="R_Ring3" pos="-0.0071 -0.0228 -0.0015">
                          <joint name="R_Ring3_x" type="hinge" pos="0 0 0" axis="1 0 0" actuatorfrcrange="0 0" stiffness="0" damping="40" armature="1" range="-1e-6 1e-6"/>
                          <joint name="R_Ring3_y" type="hinge" pos="0 0 0" axis="0 1 0" actuatorfrcrange="0 0" stiffness="0" damping="40" armature="1" range="-1e-6 1e-6"/>
                          <joint name="R_Ring3_z" type="hinge" pos="0 0 0" axis="0 0 1" actuatorfrcrange="0 0" stiffness="0" damping="40" armature="1" range="-1e-6 1e-6"/>
                          <geom type="mesh" mesh="R_Ring3_mesh" density="1000" contype="1" conaffinity="1"/>
                        </body>
                      </body>
                    </body>
                    <body name="R_Thumb1" pos="0.0259 -0.0386 -0.0211">
                      <joint name="R_Thumb1_x" type="hinge" pos="0 0 0" axis="1 0 0" actuatorfrcrange="0 0" stiffness="0" damping="40" armature="1" range="-1e-6 1e-6"/>
                      <joint name="R_Thumb1_y" type="hinge" pos="0 0 0" axis="0 1 0" actuatorfrcrange="0 0" stiffness="0" damping="40" armature="1" range="-1e-6 1e-6"/>
                      <joint name="R_Thumb1_z" type="hinge" pos="0 0 0" axis="0 0 1" actuatorfrcrange="0 0" stiffness="0" damping="40" armature="1" range="-1e-6 1e-6"/>
                      <geom type="mesh" mesh="R_Thumb1_mesh" density="1000" contype="1" conaffinity="1"/>
                      <body name="R_Thumb2" pos="0.025 -0.017 0.001">
                        <joint name="R_Thumb2_x" type="hinge" pos="0 0 0" axis="1 0 0" actuatorfrcrange="0 0" stiffness="0" damping="40" armature="1" range="-1e-6 1e-6"/>
                        <joint name="R_Thumb2_y" type="hinge" pos="0 0 0" axis="0 1 0" actuatorfrcrange="0 0" stiffness="0" damping="40" armature="1" range="-1e-6 1e-6"/>
                        <joint name="R_Thumb2_z" type="hinge" pos="0 0 0" axis="0 0 1" actuatorfrcrange="0 0" stiffness="0" damping="40" armature="1" range="-1e-6 1e-6"/>
                        <geom type="mesh" mesh="R_Thumb2_mesh" density="1000" contype="1" conaffinity="1"/>
                        <body name="R_Thumb3" pos="0.0155 -0.0205 -0.0052">
                          <joint name="R_Thumb3_x" type="hinge" pos="0 0 0" axis="1 0 0" actuatorfrcrange="0 0" stiffness="0" damping="40" armature="1" range="-1e-6 1e-6"/>
                          <joint name="R_Thumb3_y" type="hinge" pos="0 0 0" axis="0 1 0" actuatorfrcrange="0 0" stiffness="0" damping="40" armature="1" range="-1e-6 1e-6"/>
                          <joint name="R_Thumb3_z" type="hinge" pos="0 0 0" axis="0 0 1" actuatorfrcrange="0 0" stiffness="0" damping="40" armature="1" range="-1e-6 1e-6"/>
                          <geom type="mesh" mesh="R_Thumb3_mesh" density="1000" contype="1" conaffinity="1"/>
                        </body>
                      </body>
                    </body>
                  </body>
                </body>
              </body>
            </body>
          </body>
        </body>
      </body>
    </body>
  </worldbody>
  <actuator>
    <motor name="L_Hip_x" joint="L_Hip_x" gear="300"/>
    <motor name="L_Hip_y" joint="L_Hip_y" gear="300"/>
    <motor name="L_Hip_z" joint="L_Hip_z" gear="300"/>
    <motor name="L_Knee_x" joint="L_Knee_x" gear="200"/>
    <motor name="L_Knee_y" joint="L_Knee_y" gear="200"/>
    <motor name="L_Knee_z" joint="L_Knee_z" gear="200"/>
    <motor name="L_Ankle_x" joint="L_Ankle_x" gear="100"/>
    <motor name="L_Ankle_y" joint="L_Ankle_y" gear="100"/>
    <motor name="L_Ankle_z" joint="L_Ankle_z" gear="100"/>
    <motor name="L_Toe_x" joint="L_Toe_x" gear="75"/>
    <motor name="L_Toe_y" joint="L_Toe_y" gear="75"/>
    <motor name="L_Toe_z" joint="L_Toe_z" gear="75"/>
    <motor name="R_Hip_x" joint="R_Hip_x" gear="300"/>
    <motor name="R_Hip_y" joint="R_Hip_y" gear="300"/>
    <motor name="R_Hip_z" joint="R_Hip_z" gear="300"/>
    <motor name="R_Knee_x" joint="R_Knee_x" gear="200"/>
    <motor name="R_Knee_y" joint="R_Knee_y" gear="200"/>
    <motor name="R_Knee_z" joint="R_Knee_z" gear="200"/>
    <motor name="R_Ankle_x" joint="R_Ankle_x" gear="100"/>
    <motor name="R_Ankle_y" joint="R_Ankle_y" gear="100"/>
    <motor name="R_Ankle_z" joint="R_Ankle_z" gear="100"/>
    <motor name="R_Toe_x" joint="R_Toe_x" gear="75"/>
    <motor name="R_Toe_y" joint="R_Toe_y" gear="75"/>
    <motor name="R_Toe_z" joint="R_Toe_z" gear="75"/>
    <motor name="Torso_x" joint="Torso_x" gear="300"/>
    <motor name="Torso_y" joint="Torso_y" gear="300"/>
    <motor name="Torso_z" joint="Torso_z" gear="300"/>
    <motor name="Spine_x" joint="Spine_x" gear="200"/>
    <motor name="Spine_y" joint="Spine_y" gear="200"/>
    <motor name="Spine_z" joint="Spine_z" gear="200"/>
    <motor name="Chest_x" joint="Chest_x" gear="150"/>
    <motor name="Chest_y" joint="Chest_y" gear="150"/>
    <motor name="Chest_z" joint="Chest_z" gear="150"/>
    <motor name="Neck_x" joint="Neck_x" gear="75"/>
    <motor name="Neck_y" joint="Neck_y" gear="75"/>
    <motor name="Neck_z" joint="Neck_z" gear="75"/>
    <motor name="Head_x" joint="Head_x" gear="25"/>
    <motor name="Head_y" joint="Head_y" gear="25"/>
    <motor name="Head_z" joint="Head_z" gear="25"/>
    <motor name="L_Thorax_x" joint="L_Thorax_x" gear="200"/>
    <motor name="L_Thorax_y" joint="L_Thorax_y" gear="200"/>
    <motor name="L_Thorax_z" joint="L_Thorax_z" gear="200"/>
    <motor name="L_Shoulder_x" joint="L_Shoulder_x" gear="150"/>
    <motor name="L_Shoulder_y" joint="L_Shoulder_y" gear="150"/>
    <motor name="L_Shoulder_z" joint="L_Shoulder_z" gear="150"/>
    <motor name="L_Elbow_x" joint="L_Elbow_x" gear="100"/>
    <motor name="L_Elbow_y" joint="L_Elbow_y" gear="100"/>
    <motor name="L_Elbow_z" joint="L_Elbow_z" gear="100"/>
    <motor name="L_Wrist_x" joint="L_Wrist_x" gear="75"/>
    <motor name="L_Wrist_y" joint="L_Wrist_y" gear="75"/>
    <motor name="L_Wrist_z" joint="L_Wrist_z" gear="75"/>
    <motor name="R_Thorax_x" joint="R_Thorax_x" gear="200"/>
    <motor name="R_Thorax_y" joint="R_Thorax_y" gear="200"/>
    <motor name="R_Thorax_z" joint="R_Thorax_z" gear="200"/>
    <motor name="R_Shoulder_x" joint="R_Shoulder_x" gear="150"/>
    <motor name="R_Shoulder_y" joint="R_Shoulder_y" gear="150"/>
    <motor name="R_Shoulder_z" joint="R_Shoulder_z" gear="150"/>
    <motor name="R_Elbow_x" joint="R_Elbow_x" gear="100"/>
    <motor name="R_Elbow_y" joint="R_Elbow_y" gear="100"/>
    <motor name="R_Elbow_z" joint="R_Elbow_z" gear="100"/>
    <motor name="R_Wrist_x" joint="R_Wrist_x" gear="75"/>
    <motor name="R_Wrist_y" joint="R_Wrist_y" gear="75"/>
    <motor name="R_Wrist_z" joint="R_Wrist_z" gear="75"/>
  </actuator>
  <contact>
    <exclude body1="Torso" body2="Chest"/>
    <exclude body1="Head" body2="Chest"/>
    <exclude body1="R_Knee" body2="R_Toe"/>
    <exclude body1="R_Knee" body2="L_Ankle"/>
    <exclude body1="R_Knee" body2="L_Toe"/>
    <exclude body1="L_Knee" body2="L_Toe"/>
    <exclude body1="L_Knee" body2="R_Ankle"/>
    <exclude body1="L_Knee" body2="R_Toe"/>
    <exclude body1="L_Shoulder" body2="Chest"/>
    <exclude body1="R_Shoulder" body2="Chest"/>
  </contact>
  <sensor/>
  <size njmax="2500" nconmax="500"/>
<visual><global offwidth="1280" offheight="720"/></visual></mujoco>