<mujoco model="smpl">
  <compiler angle="radian" />
  <default>
    <motor ctrlrange="-1 1" ctrllimited="true" />
    <geom condim="1" friction="1.0 0.05 0.05" solimp=".9 .99 .003" solref=".015 1" />
    <joint limited="true" solimplimit="0 .99 .01" />
    <site size=".04" group="3" />
    <default class="force-torque">
      <site type="box" size=".01 .01 .02" rgba="1 0 0 1" />
    </default>
    <default class="touch">
      <site type="capsule" rgba="0 0 1 .3" />
    </default>
  </default>
  <worldbody>
    <body name="Pelvis" pos="0 0 0">
      <freejoint name="Pelvis" />
      <body name="L_Hip" pos="-0.0068 0.0695 -0.0914">
        <joint name="L_Hip_x" type="hinge" pos="0 0 0" axis="1 0 0" actuatorfrcrange="-300 300" stiffness="500" damping="50" armature="0.02" range="-0.5236 1.5708" />
        <joint name="L_Hip_y" type="hinge" pos="0 0 0" axis="0 1 0" actuatorfrcrange="-300 300" stiffness="500" damping="50" armature="0.02" range="-2.4435 1.0472" />
        <joint name="L_Hip_z" type="hinge" pos="0 0 0" axis="0 0 1" actuatorfrcrange="-300 300" stiffness="500" damping="50" armature="0.02" range="-0.6109 1.0472" />
        <body name="L_Knee" pos="-0.0045 0.0343 -0.3752">
          <joint name="L_Knee_x" type="hinge" pos="0 0 0" axis="1 0 0" actuatorfrcrange="-200 200" stiffness="500" damping="50" armature="0.02" range="-0.5236 0.5236" />
          <joint name="L_Knee_y" type="hinge" pos="0 0 0" axis="0 1 0" actuatorfrcrange="-200 200" stiffness="500" damping="50" armature="0.02" range="0 2.7925" />
          <joint name="L_Knee_z" type="hinge" pos="0 0 0" axis="0 0 1" actuatorfrcrange="-200 200" stiffness="500" damping="50" armature="0.02" range="-0.5236 0.5236" />
          <body name="L_Ankle" pos="-0.0437 -0.0136 -0.398">
            <joint name="L_Ankle_x" type="hinge" pos="0 0 0" axis="1 0 0" actuatorfrcrange="-100 100" stiffness="400" damping="40" armature="0.02" range="-0.5236 0.5236" />
            <joint name="L_Ankle_y" type="hinge" pos="0 0 0" axis="0 1 0" actuatorfrcrange="-100 100" stiffness="400" damping="40" armature="0.02" range="-0.9599 0.9599" />
            <joint name="L_Ankle_z" type="hinge" pos="0 0 0" axis="0 0 1" actuatorfrcrange="-100 100" stiffness="400" damping="40" armature="0.02" range="-0.6981 0.6981" />
            <body name="L_Toe" pos="0.1193 0.0124 -0.0258">
              <joint name="L_Toe_x" type="hinge" pos="0 0 0" axis="1 0 0" actuatorfrcrange="-75 75" stiffness="200" damping="20" armature="0.02" range="-0.5236 0.5236" />
              <joint name="L_Toe_y" type="hinge" pos="0 0 0" axis="0 1 0" actuatorfrcrange="-75 75" stiffness="200" damping="20" armature="0.02" range="-1.0472 1.0472" />
              <joint name="L_Toe_z" type="hinge" pos="0 0 0" axis="0 0 1" actuatorfrcrange="-75 75" stiffness="200" damping="20" armature="0.02" range="-0.5236 0.5236" />
              <geom type="box" pos="0.023038 0.028710 -0.002319" quat="0.999986 0.002316 0.002404 -0.004045" size="0.0512 0.0511 0.0222" density="348.643194" />
            </body>
            <geom type="box" pos="0.019061 0.041993 -0.002924" quat="0.999986 0.002316 0.002404 -0.004045" size="0.0882 0.0538 0.0467" density="406.139068" />
          </body>
          <geom type="capsule" contype="1" conaffinity="1" fromto="-0.015548 0.021243 -0.059293 -0.038822 -0.007378 -0.295920" size="0.0603" density="997.146534" />
        </body>
        <geom type="capsule" contype="1" conaffinity="1" fromto="-0.006680 0.019453 -0.070117 -0.010837 0.053776 -0.284242" size="0.0711" density="1090.054895" />
      </body>
      <body name="R_Hip" pos="-0.0043 -0.0677 -0.0905">
        <joint name="R_Hip_x" type="hinge" pos="0 0 0" axis="1 0 0" actuatorfrcrange="-300 300" stiffness="500" damping="50" armature="0.02" range="-1.5708 0.5236" />
        <joint name="R_Hip_y" type="hinge" pos="0 0 0" axis="0 1 0" actuatorfrcrange="-300 300" stiffness="500" damping="50" armature="0.02" range="-2.4435 1.0472" />
        <joint name="R_Hip_z" type="hinge" pos="0 0 0" axis="0 0 1" actuatorfrcrange="-300 300" stiffness="500" damping="50" armature="0.02" range="-1.0472 0.6109" />
        <body name="R_Knee" pos="-0.0089 -0.0383 -0.3826">
          <joint name="R_Knee_x" type="hinge" pos="0 0 0" axis="1 0 0" actuatorfrcrange="-200 200" stiffness="500" damping="50" armature="0.02" range="-0.5236 0.5236" />
          <joint name="R_Knee_y" type="hinge" pos="0 0 0" axis="0 1 0" actuatorfrcrange="-200 200" stiffness="500" damping="50" armature="0.02" range="0 2.7925" />
          <joint name="R_Knee_z" type="hinge" pos="0 0 0" axis="0 0 1" actuatorfrcrange="-200 200" stiffness="500" damping="50" armature="0.02" range="-0.5236 0.5236" />
          <body name="R_Ankle" pos="-0.0423 0.0158 -0.3984">
            <joint name="R_Ankle_x" type="hinge" pos="0 0 0" axis="1 0 0" actuatorfrcrange="-100 100" stiffness="400" damping="40" armature="0.02" range="-0.5236 0.5236" />
            <joint name="R_Ankle_y" type="hinge" pos="0 0 0" axis="0 1 0" actuatorfrcrange="-100 100" stiffness="400" damping="40" armature="0.02" range="-0.9599 0.9599" />
            <joint name="R_Ankle_z" type="hinge" pos="0 0 0" axis="0 0 1" actuatorfrcrange="-100 100" stiffness="400" damping="40" armature="0.02" range="-0.6981 0.6981" />
            <body name="R_Toe" pos="0.1193 -0.0124 -0.0258">
              <joint name="R_Toe_x" type="hinge" pos="0 0 0" axis="1 0 0" actuatorfrcrange="-75 75" stiffness="200" damping="20" armature="0.02" range="-0.5236 0.5236" />
              <joint name="R_Toe_y" type="hinge" pos="0 0 0" axis="0 1 0" actuatorfrcrange="-75 75" stiffness="200" damping="20" armature="0.02" range="-1.0472 1.0472" />
              <joint name="R_Toe_z" type="hinge" pos="0 0 0" axis="0 0 1" actuatorfrcrange="-75 75" stiffness="200" damping="20" armature="0.02" range="-0.5236 0.5236" />
              <geom type="box" pos="0.021475 -0.020679 0.003507" quat="0.999986 0.002316 0.002404 -0.004045" size="0.0512 0.051 0.0222" density="349.326808" />
            </body>
            <geom type="box" pos="0.017499 -0.032096 0.002803" quat="0.999986 0.002316 0.002404 -0.004045" size="0.0882 0.0538 0.0467" density="406.139068" />
          </body>
          <geom type="capsule" contype="1" conaffinity="1" fromto="-0.016247 -0.005155 -0.050779 -0.031314 0.006175 -0.290859" size="0.0624" density="919.897980" />
        </body>
        <geom type="capsule" contype="1" conaffinity="1" fromto="-0.005691 -0.012642 -0.079921 -0.016491 -0.038609 -0.284994" size="0.0706" density="1163.523790" />
      </body>
      <body name="Torso" pos="-0.0267 -0.0025 0.109">
        <joint name="Torso_x" type="hinge" pos="0 0 0" axis="1 0 0" actuatorfrcrange="-300 300" stiffness="1000" damping="100" armature="0.02" range="-1.0472 1.0472" />
        <joint name="Torso_y" type="hinge" pos="0 0 0" axis="0 1 0" actuatorfrcrange="-300 300" stiffness="1000" damping="100" armature="0.02" range="-1.0472 1.5708" />
        <joint name="Torso_z" type="hinge" pos="0 0 0" axis="0 0 1" actuatorfrcrange="-300 300" stiffness="1000" damping="100" armature="0.02" range="-0.8727 0.8727" />
        <body name="Spine" pos="0.0011 0.0055 0.1352">
          <joint name="Spine_x" type="hinge" pos="0 0 0" axis="1 0 0" actuatorfrcrange="-200 200" stiffness="1000" damping="100" armature="0.02" range="-1.0472 1.0472" />
          <joint name="Spine_y" type="hinge" pos="0 0 0" axis="0 1 0" actuatorfrcrange="-200 200" stiffness="1000" damping="100" armature="0.02" range="-1.0472 1.5708" />
          <joint name="Spine_z" type="hinge" pos="0 0 0" axis="0 0 1" actuatorfrcrange="-200 200" stiffness="1000" damping="100" armature="0.02" range="-0.8727 0.8727" />
          <body name="Chest" pos="0.0254 0.0015 0.0529">
            <joint name="Chest_x" type="hinge" pos="0 0 0" axis="1 0 0" actuatorfrcrange="-150 150" stiffness="1000" damping="100" armature="0.02" range="-1.0472 1.0472" />
            <joint name="Chest_y" type="hinge" pos="0 0 0" axis="0 1 0" actuatorfrcrange="-150 150" stiffness="1000" damping="100" armature="0.02" range="-1.0472 1.5708" />
            <joint name="Chest_z" type="hinge" pos="0 0 0" axis="0 0 1" actuatorfrcrange="-150 150" stiffness="1000" damping="100" armature="0.02" range="-0.8727 0.8727" />
            <body name="Neck" pos="-0.0429 -0.0028 0.2139">
              <joint name="Neck_x" type="hinge" pos="0 0 0" axis="1 0 0" actuatorfrcrange="-75 75" stiffness="500" damping="50" armature="0.02" range="-0.8727 0.8727" />
              <joint name="Neck_y" type="hinge" pos="0 0 0" axis="0 1 0" actuatorfrcrange="-75 75" stiffness="500" damping="50" armature="0.02" range="-0.6981 1.0472" />
              <joint name="Neck_z" type="hinge" pos="0 0 0" axis="0 0 1" actuatorfrcrange="-75 75" stiffness="500" damping="50" armature="0.02" range="-0.7854 0.7854" />
              <body name="Head" pos="0.0513 0.0052 0.065">
                <joint name="Head_x" type="hinge" pos="0 0 0" axis="1 0 0" actuatorfrcrange="-25 25" stiffness="200" damping="20" armature="0.02" range="-0.8727 0.8727" />
                <joint name="Head_y" type="hinge" pos="0 0 0" axis="0 1 0" actuatorfrcrange="-25 25" stiffness="200" damping="20" armature="0.02" range="-0.6981 1.0472" />
                <joint name="Head_z" type="hinge" pos="0 0 0" axis="0 0 1" actuatorfrcrange="-25 25" stiffness="200" damping="20" armature="0.02" range="-0.7854 0.7854" />
                <geom type="box" pos="-0.027757 -0.009184 0.104107" quat="0.999986 0.002316 0.002404 -0.004045" size="0.0791 0.0629 0.1116" density="808.496445" />
              </body>
              <geom type="capsule" contype="1" conaffinity="1" fromto="0.004469 -0.013165 0.003452 0.016247 0.003517 0.095175" size="0.0462" density="365.906451" />
            </body>
            <body name="L_Thorax" pos="-0.0341 0.0788 0.1217">
              <joint name="L_Thorax_x" type="hinge" pos="0 0 0" axis="1 0 0" actuatorfrcrange="-200 200" stiffness="500" damping="50" armature="0.02" range="-0.6981 0.5236" />
              <joint name="L_Thorax_y" type="hinge" pos="0 0 0" axis="0 1 0" actuatorfrcrange="-200 200" stiffness="500" damping="50" armature="0.02" range="-0.5236 0.5236" />
              <joint name="L_Thorax_z" type="hinge" pos="0 0 0" axis="0 0 1" actuatorfrcrange="-200 200" stiffness="500" damping="50" armature="0.02" range="-0.5236 0.5236" />
              <body name="L_Shoulder" pos="-0.0089 0.091 0.0305">
                <joint name="L_Shoulder_x" type="hinge" pos="0 0 0" axis="1 0 0" actuatorfrcrange="-150 150" stiffness="400" damping="40" armature="0.02" range="-2.3562 1.5708" />
                <joint name="L_Shoulder_y" type="hinge" pos="0 0 0" axis="0 1 0" actuatorfrcrange="-150 150" stiffness="400" damping="40" armature="0.02" range="-1.5708 1.5708" />
                <joint name="L_Shoulder_z" type="hinge" pos="0 0 0" axis="0 0 1" actuatorfrcrange="-150 150" stiffness="400" damping="40" armature="0.02" range="-2.7925 1.0472" />
                <body name="L_Elbow" pos="-0.0275 0.2596 -0.0128">
                  <joint name="L_Elbow_x" type="hinge" pos="0 0 0" axis="1 0 0" actuatorfrcrange="-100 100" stiffness="300" damping="30" armature="0.02" range="-0.5236 0.5236" />
                  <joint name="L_Elbow_y" type="hinge" pos="0 0 0" axis="0 1 0" actuatorfrcrange="-100 100" stiffness="300" damping="30" armature="0.02" range="-0.5236 0.5236" />
                  <joint name="L_Elbow_z" type="hinge" pos="0 0 0" axis="0 0 1" actuatorfrcrange="-100 100" stiffness="300" damping="30" armature="0.02" range="-2.7925 0" />
                  <body name="L_Wrist" pos="-0.0012 0.2492 0.009">
                    <joint name="L_Wrist_x" type="hinge" pos="0 0 0" axis="1 0 0" actuatorfrcrange="-75 75" stiffness="200" damping="20" armature="0.02" range="-1.5708 1.5708" />
                    <joint name="L_Wrist_y" type="hinge" pos="0 0 0" axis="0 1 0" actuatorfrcrange="-75 75" stiffness="200" damping="20" armature="0.02" range="-1.5708 1.5708" />
                    <joint name="L_Wrist_z" type="hinge" pos="0 0 0" axis="0 0 1" actuatorfrcrange="-75 75" stiffness="200" damping="20" armature="0.02" range="-1.0472 1.0472" />
                    <body name="L_Hand" pos="-0.0149 0.084 -0.0082">
                      <joint name="L_Hand_x" type="hinge" pos="0 0 0" axis="1 0 0" actuatorfrcrange="-50 50" stiffness="100" damping="10" armature="0.02" range="-1.5708 1.5708" />
                      <joint name="L_Hand_y" type="hinge" pos="0 0 0" axis="0 1 0" actuatorfrcrange="-50 50" stiffness="100" damping="10" armature="0.02" range="-1.5708 1.5708" />
                      <joint name="L_Hand_z" type="hinge" pos="0 0 0" axis="0 0 1" actuatorfrcrange="-50 50" stiffness="100" damping="10" armature="0.02" range="-1.5708 1.5708" />
                      <geom type="sphere" contype="1" conaffinity="1" pos="0.002823 -0.038296 -0.018826" size="0.041620" density="530.864244" />
                    </body>
                    <geom type="box" pos="-0.005156 0.054835 -0.030081" quat="0.999986 0.002316 0.002404 -0.004045" size="0.0428 0.0436 0.0177" density="1128.126878" />
                  </body>
                  <geom type="capsule" contype="1" conaffinity="1" fromto="-0.007192 0.054244 -0.045639 -0.005111 0.201748 -0.027063" size="0.0471" density="734.799835" />
                </body>
                <geom type="capsule" contype="1" conaffinity="1" fromto="0.007933 0.063452 -0.007307 -0.024557 0.214321 -0.050350" size="0.0631" density="478.484804" />
              </body>
              <geom type="capsule" contype="1" conaffinity="1" fromto="0.023793 -0.004707 -0.008966 0.013320 0.076921 0.025864" size="0.0572" density="409.348993" />
            </body>
            <body name="R_Thorax" pos="-0.0386 -0.0818 0.1188">
              <joint name="R_Thorax_x" type="hinge" pos="0 0 0" axis="1 0 0" actuatorfrcrange="-200 200" stiffness="500" damping="50" armature="0.02" range="-0.5236 0.6981" />
              <joint name="R_Thorax_y" type="hinge" pos="0 0 0" axis="0 1 0" actuatorfrcrange="-200 200" stiffness="500" damping="50" armature="0.02" range="-0.5236 0.5236" />
              <joint name="R_Thorax_z" type="hinge" pos="0 0 0" axis="0 0 1" actuatorfrcrange="-200 200" stiffness="500" damping="50" armature="0.02" range="-0.5236 0.5236" />
              <body name="R_Shoulder" pos="-0.0091 -0.096 0.0326">
                <joint name="R_Shoulder_x" type="hinge" pos="0 0 0" axis="1 0 0" actuatorfrcrange="-150 150" stiffness="400" damping="40" armature="0.02" range="-1.5708 2.3562" />
                <joint name="R_Shoulder_y" type="hinge" pos="0 0 0" axis="0 1 0" actuatorfrcrange="-150 150" stiffness="400" damping="40" armature="0.02" range="-1.5708 1.5708" />
                <joint name="R_Shoulder_z" type="hinge" pos="0 0 0" axis="0 0 1" actuatorfrcrange="-150 150" stiffness="400" damping="40" armature="0.02" range="-1.0472 2.7925" />
                <body name="R_Elbow" pos="-0.0214 -0.2537 -0.0133">
                  <joint name="R_Elbow_x" type="hinge" pos="0 0 0" axis="1 0 0" actuatorfrcrange="-100 100" stiffness="300" damping="30" armature="0.02" range="-0.5236 0.5236" />
                  <joint name="R_Elbow_y" type="hinge" pos="0 0 0" axis="0 1 0" actuatorfrcrange="-100 100" stiffness="300" damping="30" armature="0.02" range="-0.5236 0.5236" />
                  <joint name="R_Elbow_z" type="hinge" pos="0 0 0" axis="0 0 1" actuatorfrcrange="-100 100" stiffness="300" damping="30" armature="0.02" range="0 2.7925" />
                  <body name="R_Wrist" pos="-0.0056 -0.2553 0.0078">
                    <joint name="R_Wrist_x" type="hinge" pos="0 0 0" axis="1 0 0" actuatorfrcrange="-75 75" stiffness="200" damping="20" armature="0.02" range="-1.5708 1.5708" />
                    <joint name="R_Wrist_y" type="hinge" pos="0 0 0" axis="0 1 0" actuatorfrcrange="-75 75" stiffness="200" damping="20" armature="0.02" range="-1.5708 1.5708" />
                    <joint name="R_Wrist_z" type="hinge" pos="0 0 0" axis="0 0 1" actuatorfrcrange="-75 75" stiffness="200" damping="20" armature="0.02" range="-1.0472 1.0472" />
                    <body name="R_Hand" pos="-0.0103 -0.0846 -0.0061">
                      <joint name="R_Hand_x" type="hinge" pos="0 0 0" axis="1 0 0" actuatorfrcrange="-50 50" stiffness="100" damping="10" armature="0.02" range="-1.5708 1.5708" />
                      <joint name="R_Hand_y" type="hinge" pos="0 0 0" axis="0 1 0" actuatorfrcrange="-50 50" stiffness="100" damping="10" armature="0.02" range="-1.5708 1.5708" />
                      <joint name="R_Hand_z" type="hinge" pos="0 0 0" axis="0 0 1" actuatorfrcrange="-50 50" stiffness="100" damping="10" armature="0.02" range="-1.5708 1.5708" />
                      <geom type="sphere" contype="1" conaffinity="1" pos="0.002743 0.038404 -0.018806" size="0.041990" density="530.883377" />
                    </body>
                    <geom type="box" pos="-0.014149 -0.060000 -0.034408" quat="0.999986 0.002316 0.002404 -0.004045" size="0.0428 0.041 0.0177" density="1273.497307" />
                  </body>
                  <geom type="capsule" contype="1" conaffinity="1" fromto="-0.004190 -0.065554 -0.018221 -0.012890 -0.211974 -0.021660" size="0.0474" density="744.287147" />
                </body>
                <geom type="capsule" contype="1" conaffinity="1" fromto="0.005373 -0.055115 -0.005140 -0.015625 -0.216665 -0.024091" size="0.0629" density="466.074504" />
              </body>
              <geom type="capsule" contype="1" conaffinity="1" fromto="0.019987 -0.004336 -0.008272 0.007476 -0.074083 0.023264" size="0.0627" density="350.132256" />
            </body>
            <geom type="capsule" contype="1" conaffinity="1" fromto="-0.007808 -0.008104 0.063538 -0.010257 -0.008939 0.075547" size="0.1233" density="1321.362526" />
          </body>
          <geom type="capsule" contype="1" conaffinity="1" fromto="0.003782 0.005196 0.032558 0.008296 0.003734 0.038029" size="0.0929" density="994.237046" />
        </body>
        <geom type="capsule" contype="1" conaffinity="1" fromto="-0.009983 0.009349 0.073920 -0.011010 0.010799 0.086532" size="0.0925" density="785.628746" />
      </body>
      <geom type="box" pos="0.009297 0.000705 -0.018533" quat="0.999986 0.002316 0.002404 -0.004045" size="0.1161 0.1271 0.0926" density="558.685486" />
    </body>
  </worldbody>
  <actuator>
    <motor name="L_Hip_x" joint="L_Hip_x" gear="300" />
    <motor name="L_Hip_y" joint="L_Hip_y" gear="300" />
    <motor name="L_Hip_z" joint="L_Hip_z" gear="300" />
    <motor name="L_Knee_x" joint="L_Knee_x" gear="200" />
    <motor name="L_Knee_y" joint="L_Knee_y" gear="200" />
    <motor name="L_Knee_z" joint="L_Knee_z" gear="200" />
    <motor name="L_Ankle_x" joint="L_Ankle_x" gear="100" />
    <motor name="L_Ankle_y" joint="L_Ankle_y" gear="100" />
    <motor name="L_Ankle_z" joint="L_Ankle_z" gear="100" />
    <motor name="L_Toe_x" joint="L_Toe_x" gear="75" />
    <motor name="L_Toe_y" joint="L_Toe_y" gear="75" />
    <motor name="L_Toe_z" joint="L_Toe_z" gear="75" />
    <motor name="R_Hip_x" joint="R_Hip_x" gear="300" />
    <motor name="R_Hip_y" joint="R_Hip_y" gear="300" />
    <motor name="R_Hip_z" joint="R_Hip_z" gear="300" />
    <motor name="R_Knee_x" joint="R_Knee_x" gear="200" />
    <motor name="R_Knee_y" joint="R_Knee_y" gear="200" />
    <motor name="R_Knee_z" joint="R_Knee_z" gear="200" />
    <motor name="R_Ankle_x" joint="R_Ankle_x" gear="100" />
    <motor name="R_Ankle_y" joint="R_Ankle_y" gear="100" />
    <motor name="R_Ankle_z" joint="R_Ankle_z" gear="100" />
    <motor name="R_Toe_x" joint="R_Toe_x" gear="75" />
    <motor name="R_Toe_y" joint="R_Toe_y" gear="75" />
    <motor name="R_Toe_z" joint="R_Toe_z" gear="75" />
    <motor name="Torso_x" joint="Torso_x" gear="300" />
    <motor name="Torso_y" joint="Torso_y" gear="300" />
    <motor name="Torso_z" joint="Torso_z" gear="300" />
    <motor name="Spine_x" joint="Spine_x" gear="200" />
    <motor name="Spine_y" joint="Spine_y" gear="200" />
    <motor name="Spine_z" joint="Spine_z" gear="200" />
    <motor name="Chest_x" joint="Chest_x" gear="150" />
    <motor name="Chest_y" joint="Chest_y" gear="150" />
    <motor name="Chest_z" joint="Chest_z" gear="150" />
    <motor name="Neck_x" joint="Neck_x" gear="75" />
    <motor name="Neck_y" joint="Neck_y" gear="75" />
    <motor name="Neck_z" joint="Neck_z" gear="75" />
    <motor name="Head_x" joint="Head_x" gear="25" />
    <motor name="Head_y" joint="Head_y" gear="25" />
    <motor name="Head_z" joint="Head_z" gear="25" />
    <motor name="L_Thorax_x" joint="L_Thorax_x" gear="200" />
    <motor name="L_Thorax_y" joint="L_Thorax_y" gear="200" />
    <motor name="L_Thorax_z" joint="L_Thorax_z" gear="200" />
    <motor name="L_Shoulder_x" joint="L_Shoulder_x" gear="150" />
    <motor name="L_Shoulder_y" joint="L_Shoulder_y" gear="150" />
    <motor name="L_Shoulder_z" joint="L_Shoulder_z" gear="150" />
    <motor name="L_Elbow_x" joint="L_Elbow_x" gear="100" />
    <motor name="L_Elbow_y" joint="L_Elbow_y" gear="100" />
    <motor name="L_Elbow_z" joint="L_Elbow_z" gear="100" />
    <motor name="L_Wrist_x" joint="L_Wrist_x" gear="75" />
    <motor name="L_Wrist_y" joint="L_Wrist_y" gear="75" />
    <motor name="L_Wrist_z" joint="L_Wrist_z" gear="75" />
    <motor name="L_Hand_x" joint="L_Hand_x" gear="50" />
    <motor name="L_Hand_y" joint="L_Hand_y" gear="50" />
    <motor name="L_Hand_z" joint="L_Hand_z" gear="50" />
    <motor name="R_Thorax_x" joint="R_Thorax_x" gear="200" />
    <motor name="R_Thorax_y" joint="R_Thorax_y" gear="200" />
    <motor name="R_Thorax_z" joint="R_Thorax_z" gear="200" />
    <motor name="R_Shoulder_x" joint="R_Shoulder_x" gear="150" />
    <motor name="R_Shoulder_y" joint="R_Shoulder_y" gear="150" />
    <motor name="R_Shoulder_z" joint="R_Shoulder_z" gear="150" />
    <motor name="R_Elbow_x" joint="R_Elbow_x" gear="100" />
    <motor name="R_Elbow_y" joint="R_Elbow_y" gear="100" />
    <motor name="R_Elbow_z" joint="R_Elbow_z" gear="100" />
    <motor name="R_Wrist_x" joint="R_Wrist_x" gear="75" />
    <motor name="R_Wrist_y" joint="R_Wrist_y" gear="75" />
    <motor name="R_Wrist_z" joint="R_Wrist_z" gear="75" />
    <motor name="R_Hand_x" joint="R_Hand_x" gear="50" />
    <motor name="R_Hand_y" joint="R_Hand_y" gear="50" />
    <motor name="R_Hand_z" joint="R_Hand_z" gear="50" />
  </actuator>
</mujoco>
